Workbook

Sheet Cashflow Budget FY27
A1: CLENT JEWELL — Personal & Business Cashflow Budget · FY27 (Jul 2026 – Jun 2027) | R1: AT A GLANCE
A2: v1.6 · Prepared 7 Jul 2026 · Updated 21 Aug 2026 · AUD · Assumption cells shaded yellow · Aug opening re-anchored to live NAB 31 Jul; Aug WalterWealth/Adam Hall zeroed (worst case); relocation costs added; $25k JIG bridge modelled Aug in / Sep out; rows 140-171 removed and subtotal formulas repai | R2: Opening cash 1 Jul | S2: =B14 -> 49153.5
A3: PERIOD | B3: 46204 | C3: 46235 | D3: 46266 | E3: 46296 | F3: 46327 | G3: 46357 | H3: 46388 | I3: 46419 | J3: 46447 | K3: 46478 | L3: 46508 | M3: 46539 | N3: FY Total | O3: Av/mo | P3: Comments / Source | R3: Cash at 31 Jul (live, post-run) | S3: =C14 -> 24437.3
A4: OPENING CASH | R4: Hub24 bridge draw (Aug) | S4: =C160 -> 25000
A5: Personal | B5: 54971.04 | C5: 2728 | D5: 1800 | P5: LIVE NAB 31 Jul 2026 (post-payment run): personal trans 1,968.95. Aug opening re-anchored to actuals, not to July closing — July closing is a forecast, this is the bank. | R5: Closing Aug-26 | S5: =C164 -> 26689.59 | T5: Aug close + Sep burn, adding back contractors ($3,550) paid 30 Sep — i.e. AFTER settlement on 28 Sep.
A6: Business | B6: -5817.54 | C6: 8075.14 | D6: 7200 | P6: LIVE NAB 31 Jul 2026: Biz Trans 7,992.60 less today's run 3,889.09 (Lizelle 869.59 + Rao 819.50 + Ronnie 2,000.00 + Nicole 200.00) = 4,103.51. | R6: Pre-settlement trough (late Sep) | S6: =C164+D119+D58+D151 -> 10931.88 | T6: Aug close + Sep burn, adding back contractors (paid 30 Sep, AFTER settlement on 28 Sep).
A7: Visa credit card | C7: -4705.29 | D7: -6850 | R7: Trough WITHOUT the bridge | S7: =S6-C160 -> -14068.12 | T7: What the trough would be if the Hub24 draw did not happen. This is the number the bridge exists to fix.
A8: Cash offset acc | C8: 17949.88 | D8: 8800 | R8: Settlement 28 Sep (net) | S8: =D158 -> 467152.42
A9: Maxxim | C9: 360.65 | D9: 360 | R9: Closing Sep-26 (post-settlement) | S9: =D164 -> 459183.71 | T9: Still assumes Oct-Jun retainers land. Not a worst case beyond September.
A10: Child support | C10: 28.92 | D10: 29 | R10: FY27 close (Jun-27) | S10: =M164 -> 270595.91 | T10: Still assumes Oct-Jun retainers land. Worst case is modelled through September only.
A11: Float | C11: 0 | D11: 0
A12: Macquarie bank - cash | C12: 0 | D12: 25000 | P12: Macquarie CMA — JIG-owned, excluded from personal/business cash (consistent with Net Worth tab).
A13: Macquarie bank - cash accelorator | C13: 0 | D13: 0 | P13: Macquarie Accelerator — JIG-owned, excluded (consistent with Net Worth tab).
A14: OPENING CASH (combined) | B14: =SUM(B5:B13) -> 49153.5 | C14: =SUM(C5:C13) -> 24437.3 | D14: =SUM(D5:D13) -> 36339 | E14: =D164 -> 459183.71 | F14: =E164 -> 441919.33 | G14: =F164 -> 427904.95 | H14: =G164 -> 414190.57 | I14: =H164 -> 396976.19 | J14: =I164 -> 382556.81 | K14: =J164 -> 368842.43 | L14: =K164 -> 308628.05 | M14: =L164 -> 278613.67 | P14: Aug opening = LIVE NAB 31 Jul 2026 actuals (re-anchor). Later months = prior month closing. Jul closing is forecast and will differ slightly from the Aug re-anchor.
A15: BUSINESS INCOME (confirmed / conservative)
A16: Pottsville Retainer | B16: 350 | C16: 350 | D16: 350 | E16: 350 | F16: 350 | G16: 350 | H16: 350 | I16: 350 | J16: 350 | K16: 350 | L16: 350 | M16: 350 | N16: =SUM(B16:M16) -> 4200 | O16: =N16/12 -> 350 | P16: Confirmed
A17: Annual Web Hosting | B17: 250 | M17: 1213.31 | N17: =SUM(B17:M17) -> 1463.31 | O17: =N17/12 -> 121.9425 | P17: One-off, billed Jun-27 (bookkeeper draft).
A18: WalterWealth | D18: 5495 | M18: 2500 | N18: =SUM(B18:M18) -> 7995 | O18: =N18/12 -> 666.25 | P18: Onboarding 59 clients Aug-Dec. WORST CASE 31 Jul 2026: Aug zeroed — not banked until invoiced/received. Oct-Jun retained.
A19: Adam Hall | C19: 5000 | M19: 2000 | N19: =SUM(B19:M19) -> 7000 | O19: =N19/12 -> 583.33333 | P19: Marketplace set-up, then monthly retainer. WORST CASE 31 Jul 2026: Aug zeroed — $5,000 expected but not banked. Oct-Jun retained.
A20: Hosting: | N20: =SUM(B20:M20) -> 0 | O20: =N20/12 -> 0
A21: Ronja Schmidt | M21: 77.39 | N21: =SUM(B21:M21) -> 77.39 | O21: =N21/12 -> 6.4491667 | P21: One-off Jun-27.
A22: Cam Sewell | M22: 475.92 | N22: =SUM(B22:M22) -> 475.92 | O22: =N22/12 -> 39.66 | P22: One-off Jun-27.
A23: Adam Hall | M23: 660 | N23: =SUM(B23:M23) -> 660 | O23: =N23/12 -> 55 | P23: One-off Jun-27.
A24: TOTAL BUSINESS INCOME | B24: =SUM(B16:B23) -> 600 | C24: =SUM(C16:C23) -> 5350 | D24: =SUM(D16:D23) -> 5845 | E24: =SUM(E16:E23) -> 350 | F24: =SUM(F16:F23) -> 350 | G24: =SUM(G16:G23) -> 350 | H24: =SUM(H16:H23) -> 350 | I24: =SUM(I16:I23) -> 350 | ... M24: =SUM(M16:M23) -> 7276.62 | N24: =SUM(B24:M24) -> 21871.62 | O24: =N24/12 -> 1822.635 | P24: Bookkeeper draft states FY income $10,453.31; itemised lines here sum via formula (retainers held 12 mo). Discrepancy flagged. FY26 Xero actual income was $454,208.71 (context only). Held conservative — income to be added by Clent; live pipeline in Asana CRM (~$262k gross unweighted).
A25: Pipeline (upside — NOT in totals)
A26: BTC — Beyond the Clinic | B26: 0 | C26: 0 | D26: 0 | E26: 0 | F26: 0 | G26: 0 | H26: 0 | I26: 0 | J26: 0 | K26: 0 | L26: 0 | M26: 0 | N26: =SUM(B26:M26) -> 0 | O26: =N26/12 -> 0 | P26: $580k setup + $40k/mo retainer; start 1 May 26; funding-dependent.
A27: All Coast Painting | B27: 0 | C27: 0 | D27: 0 | E27: 0 | F27: 0 | G27: 0 | H27: 0 | I27: 0 | J27: 0 | K27: 0 | L27: 0 | M27: 0 | N27: =SUM(B27:M27) -> 0 | O27: =N27/12 -> 0 | P27: $10k setup + $1k/mo.
A28: Meridiam | B28: 0 | C28: 0 | D28: 0 | E28: 0 | F28: 0 | G28: 0 | H28: 0 | I28: 0 | J28: 0 | K28: 0 | L28: 0 | M28: 0 | N28: =SUM(B28:M28) -> 0 | O28: =N28/12 -> 0 | P28: $5k setup + $1k/mo.
A29: Walter Wealth | B29: 0 | C29: 0 | D29: 0 | E29: 0 | F29: 0 | G29: 0 | H29: 0 | I29: 0 | J29: 0 | K29: 0 | L29: 0 | M29: 0 | N29: =SUM(B29:M29) -> 0 | O29: =N29/12 -> 0 | P29: $2.5k setup + $1k/mo.
A30: Evolve with Us | B30: 0 | C30: 0 | D30: 0 | E30: 0 | F30: 0 | G30: 0 | H30: 0 | I30: 0 | J30: 0 | K30: 0 | L30: 0 | M30: 0 | N30: =SUM(B30:M30) -> 0 | O30: =N30/12 -> 0 | P30: $12.7k + $1k/mo (cancelled for cash reasons; may return $3,150/mo).
A31: Matt | Trader | B31: 0 | C31: 0 | D31: 0 | E31: 0 | F31: 0 | G31: 0 | H31: 0 | I31: 0 | J31: 0 | K31: 0 | L31: 0 | M31: 0 | N31: =SUM(B31:M31) -> 0 | O31: =N31/12 -> 0 | P31: $25k (proposal).
A32: Trent Electrician | B32: 0 | C32: 0 | D32: 0 | E32: 0 | F32: 0 | G32: 0 | H32: 0 | I32: 0 | J32: 0 | K32: 0 | L32: 0 | M32: 0 | N32: =SUM(B32:M32) -> 0 | O32: =N32/12 -> 0 | P32: $25k (proposal).
A33: Undisputed Nutrition | B33: 0 | C33: 0 | D33: 0 | E33: 0 | F33: 0 | G33: 0 | H33: 0 | I33: 0 | J33: 0 | K33: 0 | L33: 0 | M33: 0 | N33: =SUM(B33:M33) -> 0 | O33: =N33/12 -> 0 | P33: $3.5k (proposal).
A34: Modinex | B34: 0 | C34: 0 | D34: 0 | E34: 0 | F34: 0 | G34: 0 | H34: 0 | I34: 0 | J34: 0 | K34: 0 | L34: 0 | M34: 0 | N34: =SUM(B34:M34) -> 0 | O34: =N34/12 -> 0 | P34: $10k (new).
A35: Global Health | B35: 0 | C35: 0 | D35: 0 | E35: 0 | F35: 0 | G35: 0 | H35: 0 | I35: 0 | J35: 0 | K35: 0 | L35: 0 | M35: 0 | N35: =SUM(B35:M35) -> 0 | O35: =N35/12 -> 0 | P35: $25k (new).
A36: Westlake | B36: 0 | C36: 0 | D36: 0 | E36: 0 | F36: 0 | G36: 0 | H36: 0 | I36: 0 | J36: 0 | K36: 0 | L36: 0 | M36: 0 | N36: =SUM(B36:M36) -> 0 | O36: =N36/12 -> 0 | P36: $3.5k (new).
A37: GTworks | B37: 0 | C37: 0 | D37: 0 | E37: 0 | F37: 0 | G37: 0 | H37: 0 | I37: 0 | J37: 0 | K37: 0 | L37: 0 | M37: 0 | N37: =SUM(B37:M37) -> 0 | O37: =N37/12 -> 0 | P37: $12.5k (new).
A38: TS Finance | B38: 0 | C38: 0 | D38: 0 | E38: 0 | F38: 0 | G38: 0 | H38: 0 | I38: 0 | J38: 0 | K38: 0 | L38: 0 | M38: 0 | N38: =SUM(B38:M38) -> 0 | O38: =N38/12 -> 0 | P38: New — value TBD.
A39: Pipeline upside (unweighted, gross) — memo only | N39: 261731 | P39: Asana sync 16 Apr 2026. Gross pipeline $261,731 — memo only, NOT added to any total.
A40: Beyond the Clinic | F40: 20000 | G40: 20000 | H40: 20000 | I40: 20000 | J40: 20000 | K40: 20000 | L40: 20000 | M40: 20000 | N40: =SUM(B40:M40) -> 160000 | O40: =N40/12 -> 13333.333 | P40: Forecast only. Not confirmed.
...

Sheet Child Support — S&K
A1: Child Support — Sierra & Kyah — 50/50 shared-cost ledger (BCSA)
A2: Reconciled to $0 on 16 Jun 2026 (per accounts).
A3: Net balance (positive = Clent owes Matina; negative = Matina owes Clent): | F3: =SUMIFS(K11:K1000,L11:L1000,"Matina")-SUMIFS(N11:N1000,L11:L1000,"Matina") -> 398.455
A4: FY27 Clent share to date: | F4: =SUMIFS(K11:K1000,B11:B1000,2027) -> 3325.38
A5: BCSA: no periodic support; Clent pays 50% school fees + 50% medical/dental after rebates. Standard uniforms each parent buys own. Automation: new claims from matinajewell@proton.me land in the Inbox section (right) for approval — NOT auto-posted.
A6: Archive: full 98-row payment history stays in the original Google Sheet "Sierra & Kyah Payments 2025" (id 17kt60-RVyy41JkgYDZZn2jvvJk80FBfsOx3OOymqbmc) — this tab is a clean forward-looking ledger from the 16 Jun 2026 reconciliation.
Q9: Updated: 22/07
A10: Date | B10: FY | C10: Term | D10: Child | E10: Category | F10: BCSA? | G10: Description | H10: Total cost | I10: Rebate | J10: Net | K10: Clent 50% | L10: Who fronted | M10: Direction | N10: Settled $ | O10: Status | P10: Running balance | Q10: Invoice link | R10: Receipt link | S10: Source email | T10: Comment | U10: MonthKey | W10: MONTHLY ROLLUP — Clent 50% by category (reconciles to cashflow kids lines)
A11: 46189 | G11: Opening balance — reconciled to $0 on 16 Jun 2026 (per accounts) | P11: 0 | W11: Month | X11: School Fees | Y11: Uniforms | Z11: Medical | AA11: Dental-Ortho | AB11: Psychology | AC11: Activities | AD11: Excursions | AE11: Other | AF11: Total Clent 50% | AG11: Settled | AH11: Still owing
A12: 46186 | B12: =IF(A12="","",IF(MONTH(A12)>=7,YEAR(A12)+1,YEAR(A12))) -> 2026 | C12: T2 2026 | D12: Kyah | E12: Activities | F12: N | G12: Jazz shoes (rep dance) | H12: 75.95 | I12: 0 | J12: =H12-I12 -> 75.95 | K12: =J12/2 -> 37.975 | L12: Matina | M12: =IF(L12="Matina","Clent owes Matina","Matina owes Clent") -> Clent owes Matina | N12: 0 | O12: Paid-in-full | P12: =P11+IF(L12="Matina",K12,0)-N12 -> 37.975 | Q12: Link | R12: Link | S12: Link | T12: Only forwarded to accounts 7 Jul; missed the 16 Jun reconciliation. Not BCSA-covered (rep-dance extra). Update: paid 15 Jul 2026 | U12: =IF(A12="","",DATE(YEAR(A12),MONTH(A12),1)) -> 46174 | W12: 46174 | X12: =SUMIFS($K$11:$K$1000,$U$11:$U$1000,$W12,$E$11:$E$1000,X$11) -> 0 | Y12: =SUMIFS($K$11:$K$1000,$U$11:$U$1000,$W12,$E$11:$E$1000,Y$11) -> 87 | Z12: =SUMIFS($K$11:$K$1000,$U$11:$U$1000,$W12,$E$11:$E$1000,Z$11) -> 0 | AA12: =SUMIFS($K$11:$K$1000,$U$11:$U$1000,$W12,$E$11:$E$1000,AA$11) -> 0 | AB12: =SUMIFS($K$11:$K$1000,$U$11:$U$1000,$W12,$E$11:$E$1000,AB$11) -> 0 | AC12: =SUMIFS($K$11:$K$1000,$U$11:$U$1000,$W12,$E$11:$E$1000,AC$11) -> 37.975 | AD12: =SUMIFS($K$11:$K$1000,$U$11:$U$1000,$W12,$E$11:$E$1000,AD$11) -> 0 | AE12: =SUMIFS($K$11:$K$1000,$U$11:$U$1000,$W12,$E$11:$E$1000,AE$11) -> 220.48 | AF12: =SUMIFS($K$11:$K$1000,$U$11:$U$1000,$W12) -> 345.455 | AG12: =SUMIFS($N$11:$N$1000,$U$11:$U$1000,$W12) -> 87 | AH12: =SUMIFS($K$11:$K$1000,$U$11:$U$1000,$W12,$L$11:$L$1000,"Matina")-SUMIFS($N$11:$N$1000,$U$11:$U$1000,$W12,$L$11:$L$1000,"Matina") -> 258.455
A13: 46195 | B13: =IF(A13="","",IF(MONTH(A13)>=7,YEAR(A13)+1,YEAR(A13))) -> 2026 | C13: T2 2026 | D13: Both | E13: Other | F13: Y | G13: 22 Jun batch: Dr Tovey appt-3 $103 (net) + dentist $71.50 + medicine $8.48 + Kyah jacket $37.50 | H13: 440.96 | I13: 0 | J13: =H13-I13 -> 440.96 | K13: =J13/2 -> 220.48 | L13: Matina | M13: =IF(L13="Matina","Clent owes Matina","Matina owes Clent") -> Clent owes Matina | N13: 0 | O13: Paid-in-full | P13: =P12+IF(L13="Matina",K13,0)-N13 -> 258.455 | R13: Link | S13: Link | T13: Status unclear — likely not actioned; dentist figure duplicates the 29-May item (paid 11 Jun) — VERIFY against receipts before paying. Grouped row (medical + $37.50 uniform). Update: paid 2 Jul 2026 | U13: =IF(A13="","",DATE(YEAR(A13),MONTH(A13),1)) -> 46174 | W13: 46204 | X13: =SUMIFS($K$11:$K$1000,$U$11:$U$1000,$W13,$E$11:$E$1000,X$11) -> 3325.38 | Y13: =SUMIFS($K$11:$K$1000,$U$11:$U$1000,$W13,$E$11:$E$1000,Y$11) -> 0 | Z13: =SUMIFS($K$11:$K$1000,$U$11:$U$1000,$W13,$E$11:$E$1000,Z$11) -> 0 | AA13: =SUMIFS($K$11:$K$1000,$U$11:$U$1000,$W13,$E$11:$E$1000,AA$11) -> 0 | AB13: =SUMIFS($K$11:$K$1000,$U$11:$U$1000,$W13,$E$11:$E$1000,AB$11) -> 0 | AC13: =SUMIFS($K$11:$K$1000,$U$11:$U$1000,$W13,$E$11:$E$1000,AC$11) -> 0 | AD13: =SUMIFS($K$11:$K$1000,$U$11:$U$1000,$W13,$E$11:$E$1000,AD$11) -> 0 | AE13: =SUMIFS($K$11:$K$1000,$U$11:$U$1000,$W13,$E$11:$E$1000,AE$11) -> 0 | AF13: =SUMIFS($K$11:$K$1000,$U$11:$U$1000,$W13) -> 3325.38 | AG13: =SUMIFS($N$11:$N$1000,$U$11:$U$1000,$W13) -> 0 | AH13: =SUMIFS($K$11:$K$1000,$U$11:$U$1000,$W13,$L$11:$L$1000,"Matina")-SUMIFS($N$11:$N$1000,$U$11:$U$1000,$W13,$L$11:$L$1000,"Matina") -> 0
A14: 46199 | B14: =IF(A14="","",IF(MONTH(A14)>=7,YEAR(A14)+1,YEAR(A14))) -> 2026 | C14: T2 2026 | D14: Sierra | E14: Uniforms | F14: N | G14: School uniform (Midford: bag/shorts/hoodie) | H14: 174 | I14: 0 | J14: =H14-I14 -> 174 | K14: =J14/2 -> 87 | L14: Matina | M14: =IF(L14="Matina","Clent owes Matina","Matina owes Clent") -> Clent owes Matina | N14: 87 | O14: Paid-in-full | P14: =P13+IF(L14="Matina",K14,0)-N14 -> 258.455 | Q14: Link | R14: Link | S14: Link | T14: Paid 6 Jul 2026 ; receipt on file 7 Jul. | U14: =IF(A14="","",DATE(YEAR(A14),MONTH(A14),1)) -> 46174 | W14: 46235 | X14: =SUMIFS($K$11:$K$1000,$U$11:$U$1000,$W14,$E$11:$E$1000,X$11) -> 0 | Y14: =SUMIFS($K$11:$K$1000,$U$11:$U$1000,$W14,$E$11:$E$1000,Y$11) -> 0 | Z14: =SUMIFS($K$11:$K$1000,$U$11:$U$1000,$W14,$E$11:$E$1000,Z$11) -> 0 | AA14: =SUMIFS($K$11:$K$1000,$U$11:$U$1000,$W14,$E$11:$E$1000,AA$11) -> 0 | AB14: =SUMIFS($K$11:$K$1000,$U$11:$U$1000,$W14,$E$11:$E$1000,AB$11) -> 0 | AC14: =SUMIFS($K$11:$K$1000,$U$11:$U$1000,$W14,$E$11:$E$1000,AC$11) -> 0 | AD14: =SUMIFS($K$11:$K$1000,$U$11:$U$1000,$W14,$E$11:$E$1000,AD$11) -> 0 | AE14: =SUMIFS($K$11:$K$1000,$U$11:$U$1000,$W14,$E$11:$E$1000,AE$11) -> 0 | AF14: =SUMIFS($K$11:$K$1000,$U$11:$U$1000,$W14) -> 0 | AG14: =SUMIFS($N$11:$N$1000,$U$11:$U$1000,$W14) -> 0 | AH14: =SUMIFS($K$11:$K$1000,$U$11:$U$1000,$W14,$L$11:$L$1000,"Matina")-SUMIFS($N$11:$N$1000,$U$11:$U$1000,$W14,$L$11:$L$1000,"Matina") -> 0
A15: 46203 | B15: =IF(A15="","",IF(MONTH(A15)>=7,YEAR(A15)+1,YEAR(A15))) -> 2026 | C15: T2 2026 | D15: Sierra | E15: Psychology | F15: Y | G15: Zanda Health psychologist | L15: Clent | M15: =IF(L15="Matina","Clent owes Matina","Matina owes Clent") -> Matina owes Clent | N15: 0 | O15: Paid-in-full | P15: =P14+IF(L15="Matina",K15,0)-N15 -> 258.455 | T15: Paid direct, outside Matina channel. Amount TBC (paid direct); neutral to the inter-parent balance. | U15: =IF(A15="","",DATE(YEAR(A15),MONTH(A15),1)) -> 46174 | W15: 46266 | X15: =SUMIFS($K$11:$K$1000,$U$11:$U$1000,$W15,$E$11:$E$1000,X$11) -> 0 | Y15: =SUMIFS($K$11:$K$1000,$U$11:$U$1000,$W15,$E$11:$E$1000,Y$11) -> 0 | Z15: =SUMIFS($K$11:$K$1000,$U$11:$U$1000,$W15,$E$11:$E$1000,Z$11) -> 0 | AA15: =SUMIFS($K$11:$K$1000,$U$11:$U$1000,$W15,$E$11:$E$1000,AA$11) -> 0 | AB15: =SUMIFS($K$11:$K$1000,$U$11:$U$1000,$W15,$E$11:$E$1000,AB$11) -> 0 | AC15: =SUMIFS($K$11:$K$1000,$U$11:$U$1000,$W15,$E$11:$E$1000,AC$11) -> 0 | AD15: =SUMIFS($K$11:$K$1000,$U$11:$U$1000,$W15,$E$11:$E$1000,AD$11) -> 0 | AE15: =SUMIFS($K$11:$K$1000,$U$11:$U$1000,$W15,$E$11:$E$1000,AE$11) -> 0 | AF15: =SUMIFS($K$11:$K$1000,$U$11:$U$1000,$W15) -> 0 | AG15: =SUMIFS($N$11:$N$1000,$U$11:$U$1000,$W15) -> 0 | AH15: =SUMIFS($K$11:$K$1000,$U$11:$U$1000,$W15,$L$11:$L$1000,"Matina")-SUMIFS($N$11:$N$1000,$U$11:$U$1000,$W15,$L$11:$L$1000,"Matina") -> 0
A16: 46205 | B16: =IF(A16="","",IF(MONTH(A16)>=7,YEAR(A16)+1,YEAR(A16))) -> 2027 | C16: T3 2026 | D16: Both | E16: School Fees | F16: Y | G16: Lindisfarne Term 3 2026 | H16: 6650.76 | I16: 0 | J16: =H16-I16 -> 6650.76 | K16: =J16/2 -> 3325.38 | L16: Clent | M16: =IF(L16="Matina","Clent owes Matina","Matina owes Clent") -> Matina owes Clent | N16: 0 | O16: Paid-in-full | P16: =P15+IF(L16="Matina",K16,0)-N16 -> 258.455 | Q16: Link | R16: Link | S16: Link | T16: Scheduled 19 Jul 2026; paid direct to school (per BCSA cl.3.4) not via Matina reimbursement. FY27. Neutral to inter-parent balance. Paid 20 Jul 2026. | U16: =IF(A16="","",DATE(YEAR(A16),MONTH(A16),1)) -> 46204 | W16: 46296 | X16: =SUMIFS($K$11:$K$1000,$U$11:$U$1000,$W16,$E$11:$E$1000,X$11) -> 0 | Y16: =SUMIFS($K$11:$K$1000,$U$11:$U$1000,$W16,$E$11:$E$1000,Y$11) -> 0 | Z16: =SUMIFS($K$11:$K$1000,$U$11:$U$1000,$W16,$E$11:$E$1000,Z$11) -> 0 | AA16: =SUMIFS($K$11:$K$1000,$U$11:$U$1000,$W16,$E$11:$E$1000,AA$11) -> 0 | AB16: =SUMIFS($K$11:$K$1000,$U$11:$U$1000,$W16,$E$11:$E$1000,AB$11) -> 0 | AC16: =SUMIFS($K$11:$K$1000,$U$11:$U$1000,$W16,$E$11:$E$1000,AC$11) -> 0 | AD16: =SUMIFS($K$11:$K$1000,$U$11:$U$1000,$W16,$E$11:$E$1000,AD$11) -> 0 | AE16: =SUMIFS($K$11:$K$1000,$U$11:$U$1000,$W16,$E$11:$E$1000,AE$11) -> 0 | AF16: =SUMIFS($K$11:$K$1000,$U$11:$U$1000,$W16) -> 0 | AG16: =SUMIFS($N$11:$N$1000,$U$11:$U$1000,$W16) -> 0 | AH16: =SUMIFS($K$11:$K$1000,$U$11:$U$1000,$W16,$L$11:$L$1000,"Matina")-SUMIFS($N$11:$N$1000,$U$11:$U$1000,$W16,$L$11:$L$1000,"Matina") -> 0
A17: 46112 | B17: =IF(A17="","",IF(MONTH(A17)>=7,YEAR(A17)+1,YEAR(A17))) -> 2026 | C17: T1 2026 | D17: Sierra | E17: Psychology | F17: Y | G17: Dr Tovey psychiatrist appt-1 ($336.50 Clent share) | H17: 673 | I17: 0 | J17: =H17-I17 -> 673 | K17: =J17/2 -> 336.5 | L17: Matina | M17: =IF(L17="Matina","Clent owes Matina","Matina owes Clent") -> Clent owes Matina | N17: 336.5 | O17: Paid-in-full | P17: =P16+IF(L17="Matina",K17,0)-N17 -> 258.455 | Q17: Link | R17: Link | S17: Link | T17: Matina claims unpaid (chased 13 & 22 Jun); accounts confirm PAID 14 May 2026 (receipt $396.50 = $336.50 + $60 Kyah dance). RESOLVE directly with Matina — do not re-pay. Nets to $0 (settled) but flagged. Paid 14 May 2026. Actual NAB transaction was $396.50 because it was bundled with a $60.00 payment for Kyah's Term 2 rep dance. | U17: =IF(A17="","",DATE(YEAR(A17),MONTH(A17),1)) -> 46082 | W17: 46327 | X17: =SUMIFS($K$11:$K$1000,$U$11:$U$1000,$W17,$E$11:$E$1000,X$11) -> 0 | Y17: =SUMIFS($K$11:$K$1000,$U$11:$U$1000,$W17,$E$11:$E$1000,Y$11) -> 0 | Z17: =SUMIFS($K$11:$K$1000,$U$11:$U$1000,$W17,$E$11:$E$1000,Z$11) -> 0 | AA17: =SUMIFS($K$11:$K$1000,$U$11:$U$1000,$W17,$E$11:$E$1000,AA$11) -> 0 | AB17: =SUMIFS($K$11:$K$1000,$U$11:$U$1000,$W17,$E$11:$E$1000,AB$11) -> 0 | AC17: =SUMIFS($K$11:$K$1000,$U$11:$U$1000,$W17,$E$11:$E$1000,AC$11) -> 0 | AD17: =SUMIFS($K$11:$K$1000,$U$11:$U$1000,$W17,$E$11:$E$1000,AD$11) -> 0 | AE17: =SUMIFS($K$11:$K$1000,$U$11:$U$1000,$W17,$E$11:$E$1000,AE$11) -> 0 | AF17: =SUMIFS($K$11:$K$1000,$U$11:$U$1000,$W17) -> 0 | AG17: =SUMIFS($N$11:$N$1000,$U$11:$U$1000,$W17) -> 0 | AH17: =SUMIFS($K$11:$K$1000,$U$11:$U$1000,$W17,$L$11:$L$1000,"Matina")-SUMIFS($N$11:$N$1000,$U$11:$U$1000,$W17,$L$11:$L$1000,"Matina") -> 0
A18: 46225 | B18: 2026 | C18: T3 2026 | D18: Kyah | E18: Activities | G18: School rep dance team at the Gold Coast Eisteddfod | H18: 20 | I18: 0 | J18: =H18-I18 -> 20 | K18: =J18/2 -> 10 | L18: Matina | M18: =IF(L18="Matina","Clent owes Matina","Matina owes Clent") -> Clent owes Matina | O18: Paid-in-full | P18: =P17+IF(L18="Matina",K18,0)-N18 -> 268.455 | Q18: Link | R18: Link | S18: Link | T18: Paid 22 Jul 2026. | W18: 46357 | X18: =SUMIFS($K$11:$K$1000,$U$11:$U$1000,$W18,$E$11:$E$1000,X$11) -> 0 | Y18: =SUMIFS($K$11:$K$1000,$U$11:$U$1000,$W18,$E$11:$E$1000,Y$11) -> 0 | Z18: =SUMIFS($K$11:$K$1000,$U$11:$U$1000,$W18,$E$11:$E$1000,Z$11) -> 0 | AA18: =SUMIFS($K$11:$K$1000,$U$11:$U$1000,$W18,$E$11:$E$1000,AA$11) -> 0 | AB18: =SUMIFS($K$11:$K$1000,$U$11:$U$1000,$W18,$E$11:$E$1000,AB$11) -> 0 | AC18: =SUMIFS($K$11:$K$1000,$U$11:$U$1000,$W18,$E$11:$E$1000,AC$11) -> 0 | AD18: =SUMIFS($K$11:$K$1000,$U$11:$U$1000,$W18,$E$11:$E$1000,AD$11) -> 0 | AE18: =SUMIFS($K$11:$K$1000,$U$11:$U$1000,$W18,$E$11:$E$1000,AE$11) -> 0 | AF18: =SUMIFS($K$11:$K$1000,$U$11:$U$1000,$W18) -> 0 | AG18: =SUMIFS($N$11:$N$1000,$U$11:$U$1000,$W18) -> 0 | AH18: =SUMIFS($K$11:$K$1000,$U$11:$U$1000,$W18,$L$11:$L$1000,"Matina")-SUMIFS($N$11:$N$1000,$U$11:$U$1000,$W18,$L$11:$L$1000,"Matina") -> 0
A19: 46213 | B19: 2026 | D19: Kyah | E19: Psychology | G19: Meg O'Brien Psychology appointment | H19: 260 | J19: 260 | K19: =260*0.5 -> 130 | L19: Matina | M19: Clent owes Matina | O19: Awaiting approval | S19: Link | T19: Not yet paid | W19: 46388 | X19: =SUMIFS($K$11:$K$1000,$U$11:$U$1000,$W19,$E$11:$E$1000,X$11) -> 0 | Y19: =SUMIFS($K$11:$K$1000,$U$11:$U$1000,$W19,$E$11:$E$1000,Y$11) -> 0 | Z19: =SUMIFS($K$11:$K$1000,$U$11:$U$1000,$W19,$E$11:$E$1000,Z$11) -> 0 | AA19: =SUMIFS($K$11:$K$1000,$U$11:$U$1000,$W19,$E$11:$E$1000,AA$11) -> 0 | AB19: =SUMIFS($K$11:$K$1000,$U$11:$U$1000,$W19,$E$11:$E$1000,AB$11) -> 0 | AC19: =SUMIFS($K$11:$K$1000,$U$11:$U$1000,$W19,$E$11:$E$1000,AC$11) -> 0 | AD19: =SUMIFS($K$11:$K$1000,$U$11:$U$1000,$W19,$E$11:$E$1000,AD$11) -> 0 | AE19: =SUMIFS($K$11:$K$1000,$U$11:$U$1000,$W19,$E$11:$E$1000,AE$11) -> 0 | AF19: =SUMIFS($K$11:$K$1000,$U$11:$U$1000,$W19) -> 0 | AG19: =SUMIFS($N$11:$N$1000,$U$11:$U$1000,$W19) -> 0 | AH19: =SUMIFS($K$11:$K$1000,$U$11:$U$1000,$W19,$L$11:$L$1000,"Matina")-SUMIFS($N$11:$N$1000,$U$11:$U$1000,$W19,$L$11:$L$1000,"Matina") -> 0
A20: 46247 | B20: 2026 | D20: Sierra | E20: Psychology | G20: Living Well Psychology | H20: 277 | O20: Awaiting approval | S20: Link | T20: Not yet paid | W20: 46419 | X20: =SUMIFS($K$11:$K$1000,$U$11:$U$1000,$W20,$E$11:$E$1000,X$11) -> 0 | Y20: =SUMIFS($K$11:$K$1000,$U$11:$U$1000,$W20,$E$11:$E$1000,Y$11) -> 0 | Z20: =SUMIFS($K$11:$K$1000,$U$11:$U$1000,$W20,$E$11:$E$1000,Z$11) -> 0 | AA20: =SUMIFS($K$11:$K$1000,$U$11:$U$1000,$W20,$E$11:$E$1000,AA$11) -> 0 | AB20: =SUMIFS($K$11:$K$1000,$U$11:$U$1000,$W20,$E$11:$E$1000,AB$11) -> 0 | AC20: =SUMIFS($K$11:$K$1000,$U$11:$U$1000,$W20,$E$11:$E$1000,AC$11) -> 0 | AD20: =SUMIFS($K$11:$K$1000,$U$11:$U$1000,$W20,$E$11:$E$1000,AD$11) -> 0 | AE20: =SUMIFS($K$11:$K$1000,$U$11:$U$1000,$W20,$E$11:$E$1000,AE$11) -> 0 | AF20: =SUMIFS($K$11:$K$1000,$U$11:$U$1000,$W20) -> 0 | AG20: =SUMIFS($N$11:$N$1000,$U$11:$U$1000,$W20) -> 0 | AH20: =SUMIFS($K$11:$K$1000,$U$11:$U$1000,$W20,$L$11:$L$1000,"Matina")-SUMIFS($N$11:$N$1000,$U$11:$U$1000,$W20,$L$11:$L$1000,"Matina") -> 0
W21: 46447 | X21: =SUMIFS($K$11:$K$1000,$U$11:$U$1000,$W21,$E$11:$E$1000,X$11) -> 0 | Y21: =SUMIFS($K$11:$K$1000,$U$11:$U$1000,$W21,$E$11:$E$1000,Y$11) -> 0 | Z21: =SUMIFS($K$11:$K$1000,$U$11:$U$1000,$W21,$E$11:$E$1000,Z$11) -> 0 | AA21: =SUMIFS($K$11:$K$1000,$U$11:$U$1000,$W21,$E$11:$E$1000,AA$11) -> 0 | AB21: =SUMIFS($K$11:$K$1000,$U$11:$U$1000,$W21,$E$11:$E$1000,AB$11) -> 0 | AC21: =SUMIFS($K$11:$K$1000,$U$11:$U$1000,$W21,$E$11:$E$1000,AC$11) -> 0 | AD21: =SUMIFS($K$11:$K$1000,$U$11:$U$1000,$W21,$E$11:$E$1000,AD$11) -> 0 | AE21: =SUMIFS($K$11:$K$1000,$U$11:$U$1000,$W21,$E$11:$E$1000,AE$11) -> 0 | AF21: =SUMIFS($K$11:$K$1000,$U$11:$U$1000,$W21) -> 0 | AG21: =SUMIFS($N$11:$N$1000,$U$11:$U$1000,$W21) -> 0 | AH21: =SUMIFS($K$11:$K$1000,$U$11:$U$1000,$W21,$L$11:$L$1000,"Matina")-SUMIFS($N$11:$N$1000,$U$11:$U$1000,$W21,$L$11:$L$1000,"Matina") -> 0
W22: 46478 | X22: =SUMIFS($K$11:$K$1000,$U$11:$U$1000,$W22,$E$11:$E$1000,X$11) -> 0 | Y22: =SUMIFS($K$11:$K$1000,$U$11:$U$1000,$W22,$E$11:$E$1000,Y$11) -> 0 | Z22: =SUMIFS($K$11:$K$1000,$U$11:$U$1000,$W22,$E$11:$E$1000,Z$11) -> 0 | AA22: =SUMIFS($K$11:$K$1000,$U$11:$U$1000,$W22,$E$11:$E$1000,AA$11) -> 0 | AB22: =SUMIFS($K$11:$K$1000,$U$11:$U$1000,$W22,$E$11:$E$1000,AB$11) -> 0 | AC22: =SUMIFS($K$11:$K$1000,$U$11:$U$1000,$W22,$E$11:$E$1000,AC$11) -> 0 | AD22: =SUMIFS($K$11:$K$1000,$U$11:$U$1000,$W22,$E$11:$E$1000,AD$11) -> 0 | AE22: =SUMIFS($K$11:$K$1000,$U$11:$U$1000,$W22,$E$11:$E$1000,AE$11) -> 0 | AF22: =SUMIFS($K$11:$K$1000,$U$11:$U$1000,$W22) -> 0 | AG22: =SUMIFS($N$11:$N$1000,$U$11:$U$1000,$W22) -> 0 | AH22: =SUMIFS($K$11:$K$1000,$U$11:$U$1000,$W22,$L$11:$L$1000,"Matina")-SUMIFS($N$11:$N$1000,$U$11:$U$1000,$W22,$L$11:$L$1000,"Matina") -> 0
W23: 46508 | X23: =SUMIFS($K$11:$K$1000,$U$11:$U$1000,$W23,$E$11:$E$1000,X$11) -> 0 | Y23: =SUMIFS($K$11:$K$1000,$U$11:$U$1000,$W23,$E$11:$E$1000,Y$11) -> 0 | Z23: =SUMIFS($K$11:$K$1000,$U$11:$U$1000,$W23,$E$11:$E$1000,Z$11) -> 0 | AA23: =SUMIFS($K$11:$K$1000,$U$11:$U$1000,$W23,$E$11:$E$1000,AA$11) -> 0 | AB23: =SUMIFS($K$11:$K$1000,$U$11:$U$1000,$W23,$E$11:$E$1000,AB$11) -> 0 | AC23: =SUMIFS($K$11:$K$1000,$U$11:$U$1000,$W23,$E$11:$E$1000,AC$11) -> 0 | AD23: =SUMIFS($K$11:$K$1000,$U$11:$U$1000,$W23,$E$11:$E$1000,AD$11) -> 0 | AE23: =SUMIFS($K$11:$K$1000,$U$11:$U$1000,$W23,$E$11:$E$1000,AE$11) -> 0 | AF23: =SUMIFS($K$11:$K$1000,$U$11:$U$1000,$W23) -> 0 | AG23: =SUMIFS($N$11:$N$1000,$U$11:$U$1000,$W23) -> 0 | AH23: =SUMIFS($K$11:$K$1000,$U$11:$U$1000,$W23,$L$11:$L$1000,"Matina")-SUMIFS($N$11:$N$1000,$U$11:$U$1000,$W23,$L$11:$L$1000,"Matina") -> 0
W24: 46539 | X24: =SUMIFS($K$11:$K$1000,$U$11:$U$1000,$W24,$E$11:$E$1000,X$11) -> 0 | Y24: =SUMIFS($K$11:$K$1000,$U$11:$U$1000,$W24,$E$11:$E$1000,Y$11) -> 0 | Z24: =SUMIFS($K$11:$K$1000,$U$11:$U$1000,$W24,$E$11:$E$1000,Z$11) -> 0 | AA24: =SUMIFS($K$11:$K$1000,$U$11:$U$1000,$W24,$E$11:$E$1000,AA$11) -> 0 | AB24: =SUMIFS($K$11:$K$1000,$U$11:$U$1000,$W24,$E$11:$E$1000,AB$11) -> 0 | AC24: =SUMIFS($K$11:$K$1000,$U$11:$U$1000,$W24,$E$11:$E$1000,AC$11) -> 0 | AD24: =SUMIFS($K$11:$K$1000,$U$11:$U$1000,$W24,$E$11:$E$1000,AD$11) -> 0 | AE24: =SUMIFS($K$11:$K$1000,$U$11:$U$1000,$W24,$E$11:$E$1000,AE$11) -> 0 | AF24: =SUMIFS($K$11:$K$1000,$U$11:$U$1000,$W24) -> 0 | AG24: =SUMIFS($N$11:$N$1000,$U$11:$U$1000,$W24) -> 0 | AH24: =SUMIFS($K$11:$K$1000,$U$11:$U$1000,$W24,$L$11:$L$1000,"Matina")-SUMIFS($N$11:$N$1000,$U$11:$U$1000,$W24,$L$11:$L$1000,"Matina") -> 0
W25: FY27 total | X25: =SUM(X12:X24) -> 3325.38 | Y25: =SUM(Y12:Y24) -> 87 | Z25: =SUM(Z12:Z24) -> 0 | AA25: =SUM(AA12:AA24) -> 0 | AB25: =SUM(AB12:AB24) -> 0 | AC25: =SUM(AC12:AC24) -> 37.975 | AD25: =SUM(AD12:AD24) -> 0 | AE25: =SUM(AE12:AE24) -> 220.48 | ... AH25: =SUM(AH12:AH24) -> 258.455
W28: INBOX — TO APPROVE (matinajewell@proton.me claims)
W29: The weekly routine appends new matinajewell@proton.me claims here; Clent moves approved ones up into the ledger. Prevents double-paying her repeat reminders.
W30: Date received | X30: From | Y30: Subject | Z30: Extracted item | AA30: Extracted amount | AB30: Suggested Clent 50% | AC30: Matched to existing? | AD30: → triage
W38: School Fees Schedule 2027
W39: Month | X39: Total cost | Y39: Clent 50% | Z39: Status | AA39: Invoice link | AB39: Receipt link | AC39: Source email | AD39: Comment
W40: 46419 | Y40: =(X40/0.5) -> 0
W41: 46478 | Y41: =(X41/0.5) -> 0
W42: 46569 | Y42: =(X42/0.5) -> 0
W43: 46661 | Y43: =(X43/0.5) -> 0

Sheet Net Worth Forecast — 1 Oct 2026
A1: CLENT JEWELL — Net Worth Forecast · 1 Oct 2026 (Post-Settlement)
A2: Forecast basis: 7 Jul 2026 net worth rolled forward through Jul–Sep 2026 (selling costs + personal/business burn) · AUD · v2.1 · Updated 31 Jul 2026 · Live formulas link to 'Net Worth 7 Jul 2026' and 'Cashflow Budget FY27' · Yellow = editable assumptions. Now reflects worst-case Aug/Sep income, relocation costs and repaired subtotal formulas.
A4: A. NET WORTH BRIDGE — 7 JUL 2026 → 1 OCT 2026
A5: ITEM | B5: AMOUNT | C5: DETAIL / SOURCE
A6: Net worth 7 Jul 2026 | B6: ='Net Worth 7 Jul 2026'!B32 -> 1226208.9 | C6: Per 'Net Worth 7 Jul 2026' tab (live formula).
A7: − Selling costs (agent commission + conveyancing + selling extras) | B7: =SUM('Cashflow Budget FY27'!D155:D157) -> -27020 | C7: Commission $30,000 + conveyancing $1,980 (quoted $1,800+GST Border Conveyancing) + extras $3,354 (live from Cashflow tab, Sep-26 column).
A8: − Personal burn Jul–Sep (net, excl. sale) | B8: =SUM('Cashflow Budget FY27'!B151:D151) -> -48061.53 | C8: Live from Cashflow NET PERSONAL CASHFLOW (Jul–Sep). Updated 31 Jul 2026: now includes relocation (removalists $2,000 + storage $400) and $1,000/mo buffer, and excludes the ClearView double-count that was inflating this line by $429/mo.
A9: − Business burn Jul–Sep (net) | B9: =SUM('Cashflow Budget FY27'!B119:D119) -> -22936.35 | C9: Live from Cashflow NET BUSINESS CASHFLOW (Jul–Sep). Updated 31 Jul 2026: worst case — no WalterWealth or Adam Hall banked in Aug or Sep. Also now correctly includes Legal $350 + BAS $1,212, which the old TOTAL BUSINESS EXPENSES formula omitted entirely.
A11: FORECAST NET WORTH 1 OCT 2026 | B11: =SUM(B6:B9) -> 1128191 | C11: ≈ $1.13M — settlement + three months of burn rolled forward. Ties exactly to the balance-sheet total in Section B below.
A13: B. FORECAST BALANCE SHEET — 1 OCT 2026
A14: ASSETS
A15: Personal cash (offset/loan repaid — fully unencumbered) | B15: ='Net Worth 7 Jul 2026'!B11+'Cashflow Budget FY27'!D158+SUM('Cashflow Budget FY27'!B151:D151) -> 474061.93 | C15: 7 Jul personal liquid + house sale net proceeds + Jul–Sep personal burn. The $25,000 JIG bridge is drawn in Aug and repaid at settlement, so it nets to zero by 1 Oct and does not appear here.
A16: Hub24 Super — Clent (flat assumption, locked) | B16: ='Net Worth 7 Jul 2026'!B15 -> 406323.88 | C16: No change assumed between 7 Jul and 1 Oct.
A17: JIG interests (Hub24 JIG + Macquarie + Div7A loan — REPAID to JIG at settlement) | B17: ='Net Worth 7 Jul 2026'!B21 -> 293874.85 | C17: Hub24 JIG + Macquarie + Div7A receivable. The $25,000 Aug sell-down does not reduce this: Hub24 falls $25k and JIG picks up a $25k loan receivable, repaid from settlement. Composition changes, total does not.
A18: Jewell Group (Trust) equity | B18: ='Net Worth 7 Jul 2026'!B22+SUM('Cashflow Budget FY27'!B119:D119) -> -9192.25 | C18: Trust equity 13,744.10 + business cashflow Jul–Sep. AMBER and now negative on worst-case income — the business is consuming personal capital monthly. Pipeline conversion (BTC/EWU/Meridiam/All Coast) is the fix, not cost cuts.
A19: TOTAL ASSETS | B19: =SUM(B15:B18) -> 1165068.4 | C19: Personal cash + Super + Entity interests.
A21: LIABILITIES
A22: Personal tax provision | B22: ='Net Worth 7 Jul 2026'!B27 -> -35000 | C22: Unchanged — payable Apr-27.
A23: Home loan (NAB …008867) | B23: 0 | C23: REPAID AT SETTLEMENT — CLEARED. Was −$1,457,705.02 at 7 Jul 2026.
A24: TOTAL LIABILITIES | B24: =B22+B23 -> -35000 | C24: Personal tax provision only — home loan cleared.
A26: NET WORTH ≈ 1 OCT 2026 (Assets − Liabilities) | B26: =B19+B24 -> 1130068.4 | C26: Cross-check: equals the bridge total in Section A (both derived from the same live inputs).
A28: ASSET MIX (1 OCT 2026) | C28: % of forecast net worth
A29: Liquid (personal cash) | B29: =B15 -> 474061.93 | C29: =B29/$B$26 -> 0.41949844
A30: Super (locked) | B30: =B16 -> 406323.88 | C30: =B30/$B$26 -> 0.35955689
A31: Entity (JIG + Trust, net) | B31: =B17+B18 -> 284682.6 | C31: =B31/$B$26 -> 0.25191625
A32: — vs 7 Jul 2026: Liquid share | B32: ='Net Worth 7 Jul 2026'!B35 -> 54971.04 | C32: ='Net Worth 7 Jul 2026'!B35/'Net Worth 7 Jul 2026'!B32 -> 0.044830079
A34: Settlement transforms the balance sheet: from ~$55k accessible to ~$472k accessible. Decisions shift from ‘survive to settlement’ to ‘deploy capital + control burn’.
A37: C. RUNWAY & SCENARIOS (HORIZON FROM 1 OCT 2026)
A38: Combined liquid cash at settlement (personal + business) | B38: ='Cashflow Budget FY27'!D164 -> 459183.71 | C38: Live from Cashflow CLOSING CASH, Sep-26 column. Bridge already repaid at settlement, so this is clean unencumbered cash.
A40: SCENARIO | B40: Personal burn/mo | C40: Business burn/mo | D40: Pipeline/BTC adj/mo | E40: Net burn/mo | F40: Runway (months) | G40: Cash-out date | H40: Notes
A41: 1. Base AU (rent $3,500, current spend) | B41: -8250 | C41: -8100 | D41: 0 | E41: =B41+C41+D41 -> -16350 | F41: =IF(E41>=0,"Cash-positive",ROUND(-$B$38/E41,1)) -> 28.1 | G41: =IF(E41>=0,"— (accumulating)",EDATE(DATE(2026,10,1),ROUND(-$B$38/E41,0))) -> 47150 | H41: Current model — AU rent + conservative business income. SUPERSEDED — Clent's edits make SEA-from-Oct the base case.
A42: 2. SE Asia comfortable (Bangkok/KL/Canggu) | B42: -6230 | C42: -8100 | D42: 0 | E42: =B42+C42+D42 -> -14330 | F42: =IF(E42>=0,"Cash-positive",ROUND(-$B$38/E42,1)) -> 32 | G42: =IF(E42>=0,"— (accumulating)",EDATE(DATE(2026,10,1),ROUND(-$B$38/E42,0))) -> 47270 | H42: All-in ≈A$4.0k/mo incl. expat health + AU return flights.
A43: 3. SE Asia lean (Chiang Mai/Da Nang/HCMC) | B43: -4530 | C43: -8100 | D43: 0 | E43: =B43+C43+D43 -> -12630 | F43: =IF(E43>=0,"Cash-positive",ROUND(-$B$38/E43,1)) -> 36.4 | G43: =IF(E43>=0,"— (accumulating)",EDATE(DATE(2026,10,1),ROUND(-$B$38/E43,0))) -> 47392 | H43: All-in ≈A$2.3k/mo incl. expat health + AU return flights. Matches Clent's base plan now (rent $1,200/mo).
A44: 4. SE Asia lean + pipeline partial | B44: -4530 | C44: -8100 | D44: 5000 | E44: =B44+C44+D44 -> -7630 | F44: =IF(E44>=0,"Cash-positive",ROUND(-$B$38/E44,1)) -> 60.2 | G44: =IF(E44>=0,"— (accumulating)",EDATE(DATE(2026,10,1),ROUND(-$B$38/E44,0))) -> 48122 | H44: +$5,000/mo net new business revenue (EWU win-back / Meridiam / All Coast).
A45: 5. SE Asia + BTC lands | B45: -4530 | C45: -8100 | D45: 34400 | E45: =B45+C45+D45 -> 21770 | F45: =IF(E45>=0,"Cash-positive",ROUND(-$B$38/E45,1)) -> Cash-positive | G45: =IF(E45>=0,"— (accumulating)",EDATE(DATE(2026,10,1),ROUND(-$B$38/E45,0))) -> — (accumulating) | H45: +$34,400/mo net — Beyond the Clinic funding decision. Cash-positive.
A46: All scenarios include BCSA obligations: 50% school fees (~$14k/yr, rising) + 50% kids' medical to ~2030/2032.
A47: Visa timing — CHANGED 31 Jul 2026: the $25k bridge CANNOT double as DTV seasoning, because it is repaid at settlement on 28 Sep. Thailand DTV needs ~A$21k seasoned ~3 months, so seasoning now starts from settlement (Oct) → apply from ~Jan 2027, not Nov 2026. Runway/cash-out dates assume the scenario's net burn holds constant from 1 Oct 2026.
A49: Updated 31 Jul 2026 · Formulas link live to 'Net Worth 7 Jul 2026' and 'Cashflow Budget FY27' · Yellow cells are editable scenario assumptions (personal burn / business burn / pipeline-BTC adjustment).

Sheet Net Worth 7 Jul 2026
A1: CLENT JEWELL — Personal Statement of Net Worth
A2: As at 7 July 2026 · AUD · v1.2 · Green = liquid, Amber = locked/entity/assumption, Red = liability · NAB/Macquarie live 7 Jul
A3: ITEM | B3: Value | C3: As-at | D3: Status | E3: Source / Notes | F3: % of Total Assets
A4: A. ASSETS
A5: Cash & Equivalents (personal)
A6: NAB Loan Offset (…422998) | B6: 52922.84 | C6: 46210 | D6: Liquid | E6: Offsets home loan. LIVE NAB internet banking 7 Jul 2026 (was $56,122.84 in 22-Jun CSV). | F6: =B6/$B$24 -> 0.019464699
A7: NAB Personal Trans (…699713) | B7: 1995.93 | C7: 46210 | D7: Liquid | E7: LIVE NAB 7 Jul 2026. | F7: =B7/$B$24 -> 0.00073409093
A8: NAB Child Support (…652565) | B8: 52.27 | C8: 46210 | D8: Liquid | E8: LIVE NAB 7 Jul 2026. | F8: =B8/$B$24 -> 1.9224588e-05
B9: 0
A10: NAB Float (…845515) | B10: 0 | C10: 46210 | D10: Liquid | E10: LIVE NAB 7 Jul 2026 — confirmed $0.00; staleness cleared. | F10: =B10/$B$24 -> 0
A11: Cash & Equivalents — subtotal | B11: =SUM(B6:B10) -> 54971.04 | D11: Liquid | E11: Personal liquid cash. Business accounts sit inside Jewell Group equity. | F11: =B11/$B$24 -> 0.020218014
A12: Property
A13: 10 Buncrana Terrace (home) | B13: 1950000 | C13: 46202 | D13: Contracted | E13: SIGNED contract 29 Jun 2026 @ $1,950,000 (purchaser M. Gyles; Coastal Property Collective). Completion 90 days after contract ≈ 27 Sep 2026. Deposit $100,000 accepted in lieu of full 10% (held in trust to completion). 8% p.a. interest if completion late. Replaces prior $2.0M assumption. | F13: =B13/$B$24 -> 0.71719815
A14: Superannuation
A15: Hub24 Super — Clent (a/c 24067445) | B15: 406323.88 | C15: 46209 | D15: Locked | E15: Accumulation, fully preserved. Since-inception report 7/7/2026. Composition 6/7/26: Managed Ptf 186,473.54; Aust Listed Sec 169,485.03; Managed Funds 37,339.38; Cash 13,025.93. Tax-free 30,624.72 / taxable 375,699.16. Beneficiaries Kyah 50% / Sierra 50%. Adviser Nick Walter. | F15: =B15/$B$24 -> 0.14944345
A16: Entity Interests
A17: Jewell Investment Group (JIG)
A18: Hub24 JIG Investment (a/c 24338104) | B18: 103285.02 | C18: 46209 | D18: Locked | E18: Owner: JIG Pty Ltd. Holdings GARP 38,581.20 / HNDQ 28,465.92 / IJP 32,145.50 / cash 4,092.40. Net deposits $92,500. | F18: =B18/$B$24 -> 0.037987603
A19: Macquarie accounts (JIG): Accelerator + CMA | B19: 14.49 | C19: 46210 | D19: Locked | E19: LIVE 7 Jul 2026 (screenshot): Cash Mgmt Accelerator 182-500|000942365818 $11.76 + Cash Mgmt Account 182-512|000974533598 $2.73 = $14.49. Both account-named JEWELL INVESTMENT GROUP PTY LTD. Staleness flag cleared. (Note: this line was previously mis-listed as a personal cash row; corrected — both Macquarie accounts are JIG-owned, not personal.) | F19: =B19/$B$24 -> 5.329334e-06
A20: Div 7A loan receivable (JIG→Trust) | B20: 190575.34 | C20: 45792 | D20: Entity | E20: 7-yr complying loan at ATO benchmark from 15 May 2025. Asset of JIG / liability of Jewell Group Trust. Recoverable from trust — amber. Adjudication #6. This receivable is repaid in full to JIG at house settlement (~27 Sep 2026) — see 'Net Worth Forecast — 1 Oct 2026' tab where it converts to settled JIG cash. | F20: =B20/$B$24 -> 0.070092452
A21: JIG — subtotal | B21: =SUM(B18:B20) -> 293874.85 | D21: Entity | E21: Hub24 + Macquarie + Div 7A receivable. | F21: =B21/$B$24 -> 0.10808538
A22: Jewell Group (Trust) — equity per Xero | B22: 13744.1 | C22: 46210 | D22: Entity | E22: Xero net equity of Jewell Group Pty Ltd (corporate trustee) 7 Jul 2026. Includes business cash & biz CC. Amber. Adjudication #6. NOTE: this Trust equity figure already nets the Div7A amount as a liability — this receivable (B20) and that embedded liability are two sides of one inter-company loan and cancel in total net worth. Removing/repaying does not change total net worth, only its composition (receivable → cash). | F22: =B22/$B$24 -> 0.0050549965
A23: Entity Interests — subtotal | B23: =B21+B22 -> 307618.95 | D23: Entity | E23: JIG + Jewell Group equity. | F23: =B23/$B$24 -> 0.11314038
A24: TOTAL ASSETS (A) | B24: =B11+B13+B15+B23 -> 2718913.9 | E24: Cash + Property + Super + Entity interests.
A25: B. LIABILITIES
A26: NAB Home Loan (…008867) | B26: -1457705 | C26: 46210 | D26: Liability | E26: 6.04% from 15 May 2026; min repayment $8,669.04/mo; $8/mo fee. Personal liability. Balance confirmed LIVE 7 Jul 2026.
A27: Personal tax provision | B27: -35000 | C27: 46507 | D27: Liability | E27: Personal tax payable Apr-27 (per Cashflow). Amber/liability.
A28: TOTAL LIABILITIES (B) | B28: =SUM(B26:B27) -> -1492705 | E28: Home loan + personal tax provision. Business credit card −$10,917.86 sits inside Jewell Group equity (memo below).
A29: (memo) NAB Biz Credit Card (•4231) | B29: -8917.86 | C29: 46210 | D29: Liability | E29: Business liability — inside Jewell Group equity, NOT added to personal liabilities. LIVE NAB 7 Jul 2026 (was −$10,917.86).
A31: C. DERIVED
A32: NET WORTH (Assets − Liabilities) | B32: =B24+B28 -> 1226208.9 | E32: Liabilities are negative, so added.
A33: Net equity — home | B33: =B13+B26 -> 492294.98 | E33: Home value − home loan.
A34: LVR % (loan ÷ home value) | B34: =-B26/B13 -> 0.74754104 | E34: Loan $1,455,828 ÷ home $1,950,000 (contracted price). Corrected 31 Jul 2026 — previously read "$2.0M".
A35: Liquid (personal cash) | B35: =B11 -> 54971.04 | D35: Liquid | E35: Accessible now.
A36: Locked (super + property + entity) | B36: =B15+B13+B23 -> 2663942.8 | D36: Locked | E36: Not readily accessible.
A38: Prepared 7 Jul 2026 · Sources: NAB/Macquarie/Hub24 exports 7 Jul 2026, Xero, bookkeeper FY27 draft · Assumptions marked yellow · See MEMO block below for the live 31 Jul 2026 position — this statement itself is deliberately left as at 7 Jul so the 'Net Worth Forecast — 1 Oct 2026' bridge keeps a single dated baseline.
A40: LIQUID vs LOCKED (mini view)
A41: Liquid (personal cash) | B41: =B35 -> 54971.04
A42: Locked (super + property + entity) | B42: =B36 -> 2663942.8
A44: MEMO — POSITION AT 31 JUL 2026 (this statement remains as at 7 Jul; figures below are the later live read)
...

Sheet Summary — Situation
A1: CLENT JEWELL — Personal Situation Summary
A2: As at 31 July 2026 · AUD · v1.3 · NAB balances confirmed live 31 Jul (post payment run) · Hub24/Macquarie live 7 Jul
A3: TOPIC | B3: DETAIL | C3: STATUS
A4: AT A GLANCE
A5: Net worth today (7 Jul 2026) | B5: $1,226,209 — see 'Net Worth 7 Jul 2026' tab.
A6: Post-settlement forecast (1 Oct 2026) | B6: ="≈ $"&TEXT('Net Worth Forecast — 1 Oct 2026'!B26,"#,##0")&" — see 'Net Worth Forecast — 1 Oct 2026' tab." -> ≈ $1,130,068 — see 'Net Worth Forecast — 1 Oct 2026' tab.
A7: Liquid after settlement | B7: ≈ $466k personal cash, fully unencumbered (home loan and offset cleared at settlement). Was ≈ $28k liquid at 31 Jul.
A8: Burn (base case) | B8: Personal ≈ $8.5k/mo Oct–Jun; business ≈ −$2.3k/mo net of confirmed income. Apr-27 spike ≈ $54k (personal tax $35k + accountant $8k + normal month). May-27 ≈ $24k (company tax $15k).
A9: Runway | B9: See 'Net Worth Forecast — 1 Oct 2026' Section C. On ≈ $445k at settlement and current burn, runway is measured in years, not months. The binding constraint is now the pre-settlement bridge, not the post-settlement runway.
A10: PERSONAL SNAPSHOT
A11: Individual | B11: Clent Jewell — sole director/owner of Jewell Group Pty Ltd & JIG. Business run through Jewell Group Trust.
A12: Family | B12: Children Kyah Lee & Sierra Jade Jewell (super beneficiaries 50/50). See Parenting note below.
A13: Home | B13: 10 Buncrana Terrace, Banora Point — SOLD (contract exchanged 29 Jun 2026) @ $1,950,000 to Minka Christine Gyles. Settlement 28 Sep 2026. Deposit $100,000 held in trust — EARLY RELEASE CONFIRMED NOT AVAILABLE (Clent, 31 Jul 2026).
A14: Net worth (est.) | B14: See 'Net Worth 7 Jul 2026' tab. Dominated by home equity + Hub24 super $406,324.
A15: Parenting | B15: No current access (family law matter). BCSA financial obligations (50% school fees + 50% medical) continue regardless and remain budgeted.
A16: NAB BANKING
A17: Home Loan (…008867) | B17: −$1,455,827.58 LIVE @ 31 Jul 2026 (was −$1,457,705.02 @ 7 Jul). 6.04% from 15 May 2026; min repayment $8,669.04/mo.
A18: Loan Offset (…422998) | B18: $26,449.88 LIVE @ 31 Jul 2026 (was $52,922.84 @ 7 Jul) — offset drawn down ≈ $26.5k over July. Counted as personal liquid cash.
A19: Biz Credit Card (•4231) | B19: −$5,174.00 LIVE @ 31 Jul 2026 (was −$8,917.86 @ 7 Jul). Limit $10,000. NOT to be used as the bridge — Clent, 31 Jul 2026.
A20: Biz Trans (…611444) | B20: $4,103.51 LIVE @ 31 Jul 2026, after the 31 Jul run (7,992.60 − 3,889.09: Lizelle 869.59 + Rao 819.50 + Ronnie 2,000 + Nicole 200).
A21: Personal Trans (…699713) | B21: $1,968.95 LIVE @ 31 Jul 2026.
A22: Child Support (…652565) | B22: $28.92 LIVE @ 31 Jul 2026.
A23: Maxxim (…426985) | B23: $367.99 LIVE @ 31 Jul 2026 — tech subscriptions account (business).
A24: Float (…845515) | B24: $0.00 LIVE @ 31 Jul 2026. Also B3 Biz Petty Cash: $0.00 live vs $663 in Xero — still to reconcile.
A25: MACQUARIE BANKING
A26: Cash Mgmt Account (JIG) | B26: Cash Management Account (182-512 | 000974533598) — $2.73 @ 7 Jul 2026. JIG-owned. THIS IS THE LANDING ACCOUNT for the $25,000 Hub24 sell-down before onward transfer to NAB.
A27: CMA Accelerator (JIG) | B27: Cash Management Accelerator (182-500 | 000942365818) — $11.76 LIVE @ 7 Jul 2026. Account name: JEWELL INVESTMENT GROUP PTY LTD. Total Macquarie $14.49.
A28: HUB24 — SUPER & INVESTMENTS
A29: Super — Clent (a/c 24067445, member 0EBUK5, joined 7/8/2020)
A30: Balance | B30: $406,323.88 @ 6 Jul 2026 — accumulation, fully preserved. (Since-inception report executed 7/7/2026; supersedes $406,963.27 @ 3 Jul.)
A31: Composition (6/7/2026) | B31: Managed Portfolios $186,473.54; Aust Listed Securities $169,485.03 (Sunbird Core SMA: ANZ, BHP, CBA, MQG, RIO, GMG); Managed Funds $37,339.38 (ARK Global Disruptive Innovation); Cash $13,025.93 (cleared $10,282.84 + pending settlement $2,743.09).
A32: Since inception (7/8/2020 → 6/7/2026) | B32: Deposits $342,079.14; withdrawals −$32,350.16; net deposits $309,728.98. Income $50,186.69 (dividends $44,410.96 + interest $5,775.73); expenses −$9,605.04; capital appreciation $56,013.25. Cumulative growth ≈ +$96,595 on net deposits (~31%).
A33: Tax components | B33: Tax-free $30,624.72; taxable (taxed) $375,699.16.
A34: Beneficiaries | B34: Binding non-lapsing (signed 2/11/2024): Kyah Lee Jewell 50%, Sierra Jade Jewell 50%. No insurance in super.
A35: Contribution | B35: FY2024 personal deductible contribution $119,675 to Hub24 Super (ABN 60 910 190 523), reducing taxable income $239,579 → $119,904.
A36: Adviser | B36: Nick Walter, Walter Wealth Advice.
A37: JIG Investment (a/c 24338104, opened 12/11/2025)
A38: Balance | B38: $103,285.02 @ 6 Jul 2026. $25,000 sell-down requested 31 Jul 2026 (lands on/around 15 Aug) → ≈ $78k remaining. Net deposits $92,500.
A39: Holdings | B39: GARP $38,581.20 (38.9%); HNDQ $28,465.92 (28.7%); IJP $32,145.50 (32.4%); cash $4,092.40. No borrowings. Same adviser.
A40: CORPORATE STRUCTURE
...

Sheet Insights & Recommendations
A1: CLENT JEWELL — Insights & Recommendations
A2: Synthesis as at 31 Jul 2026 · Companion to 'Net Worth Forecast — 1 Oct 2026' · General information only — not financial, tax or legal advice; verify with your accountant/conveyancer before acting.
A3: TOPIC | B3: DETAIL | C3: PRIORITY
A4: TOPLINE
A5: The settlement changes the game | B5: Settlement on 28 Sep 2026 turns ≈ $28k accessible cash into ≈ $445k. Net worth ≈ $1.12M, ~41% liquid (was ~2%). Decision mode shifts from "bridge to settlement" to "deploy capital + control burn".
A6: Watch late September, not August | B6: The trough is NOT August — it is late September, immediately before settlement. Without a bridge, combined cash reaches ≈ −$10.4k. The $25,000 JIG draw (landing ~15 Aug) lifts the trough to ≈ +$14.6k. August closes at ≈ $32.5k with the bridge in hand.
A7: Burn is the controllable lever | B7: Business runs ≈ −$2.3k/mo net of confirmed income once Oct–Jun retainers land; personal ≈ $8.5k/mo. Pipeline conversion is worth far more than any remaining cost cut — the subscription base is already near the floor.
A8: Runway | B8: Base AU ≈ 27 months. SEA lean ≈ 35 months. SEA + $5k/mo net new revenue ≈ 58 months. BTC landing flips cash-positive. Every path to a long runway runs through revenue, not just frugality.
A9: April 2027 is still the crunch | B9: Personal tax $35k + accountant $8k + a normal month ≈ $54k out in April, then ≈ $24k in May (company tax $15k). Pre-position from sale proceeds in October; consider a TWB payment plan.
A10: CASH & RUNWAY
A11: Bridge — RESOLVED | B11: Deposit early release: CONFIRMED NOT AVAILABLE. Business credit card: ruled out by Clent (largely committed to work spend, $10k limit). Contractor timing: locked, month end. ADOPTED: $25,000 JIG Hub24 sell-down, requested 31 Jul 2026, landing ~15 Aug, repaid at settlement. A second tranche of similar size is available at ~3 business days notice if invoicing slips further. | C11: DONE
A12: Post-settlement allocation | B12: Don't park ≈ $466k in a transaction account. Suggested: 6-mo expenses (~$60k) in a high-interest saver; balance tiered (TDs/ETFs — decide entity and get advice). At ~5%, $350k earns ≈ $17.5k/yr, offsetting roughly a sixth of base burn.
A13: Trust equity goes negative | B13: ="On conservative income, Jewell Group Trust equity ≈ −$"&TEXT(-'Net Worth Forecast — 1 Oct 2026'!B18/1000,"#,##0.0")&"k by Oct-26. Not a crisis (you fund it), but it means the business is consuming personal capital monthly." -> On conservative income, Jewell Group Trust equity ≈ −$9.2k by Oct-26. Not a crisis (you fund it), but it means the business is consuming personal capital monthly.
A14: SALE EXECUTION
A15: Completion mechanics | B15: Contract 29 Jun + 90 days ≈ 27 Sep 2026; 8% p.a. penalty interest if purchaser delays. Get payout figure + commission invoice confirmed by Border Conveyancing; both are still estimates in this model ($30k commission, $2k conveyancing, $3.4k extras).
A16: STRUCTURE & TAX
A17: Stay an AU tax resident | B17: With kids, co-parent, trust and business in AU, you’ll almost certainly remain an AU tax resident — and you want to: preserves franking credits, main-residence exemption already used, avoids CGT event I1 deemed disposal and s98 trust complications (trustee taxed at 45% for non-resident beneficiaries). Get written confirmation from your accountant BEFORE departure. (General info, not tax advice.)
A18: Div 7A — two loans now | B18: (1) The existing $190,575 JIG→Trust loan settles to JIG post-sale, accountant-agreed. (2) NEW: the $25,000 bridge drawn Aug and repaid from settlement 28 Sep — same FY, well before lodgement day, so no deemed dividend arises. Tell TWB it happened and confirm which entity receives it, so it is coded rather than discovered at year end.
A19: JIG is the war chest, not a wallet | B19: ≈ $294k in JIG, of which Hub24 ≈ $103k is sellable at ~2 days notice — that liquidity is what makes the bridge work. Drawing it personally still creates a Div 7A loan, so keep drawings short-dated and documented. Post-settlement, plan dividends/distributions with the accountant rather than ad-hoc draws.
A20: Xero hygiene | B20: 3 + 8 unreconciled items; petty cash $663 in Xero vs $0 at bank; Biz Trans out by ~$3.2k. Clean before BAS (due 28 Jul).
A21: Bookkeeping hygiene | B21: Xero FY26 shows Advisory $4,500 + Bank Fees $2,712 that the FY27 draft omitted, and a Hubdoc forwarding loop risking duplicate entries. Reconcile the FY27 model against Xero actuals before relying on it.
A22: Super contribution | B22: Most tax-effective lever available; Clent deferring additional contributions until income/Secura opportunity lands, then revisit (he made $119k personal deductible FY24).
A23: WORK GOALS
A24: Revenue isn’t the problem, margin is | B24: FY26: $454k income but only $17k net (COGS 65%, contractor-heavy). FY27 plan must fix margin, not just volume.
A25: Pipeline is the runway multiplier | B25: $262k gross pipeline sits at $0 in the base. Converting even $5k/mo net doubles runway. Priorities: BTC funding status (the +$34k/mo swing), EWU win-back ($3,150/mo — cancelled on cash, not relationship), Meridiam + All Coast starts.
A26: AI tooling spend | B26: Now Anthropic $400 + $500 tokens, ChatGPT $30 + $250 tokens ≈ $14.2k/yr — Clent already capped tokens; 'Check' review of the 6 flagged subs (Google Workspace, Go High Level, Wildjar, WPMUDEV, Brave, Gamma) is the next saving. | SaaS sprawl: Hubdoc shows Slack, Supabase, OpenAI API, Webroot, Workspace AI add-on not previously budgeted (~$2k+/yr on top). Plus 6 subs Clent flagged 'Check'. A single subscription audit likely recovers $3–5k/yr.
A27: SEA works for clients | B27: UTC+7/8 is only 2–3h behind AEST — client calls unaffected.
A28: SE ASIA MOVE
A29: Visa: Thailand DTV is the fit | B29: 5-year multi-entry, ~THB 500k (~A$21k) savings requirement, seasoned ~3 months. TIMING CHANGED 31 Jul 2026: the $25k bridge CANNOT double as seasoning — it is repaid at settlement. Season from settlement proceeds in October → apply from ~Jan 2027 (was Nov 2026). Malaysia DE Rantau is plan B; Bali highest friction.
A30: All-in cost | B30: Lean (Chiang Mai/Da Nang/HCMC) ≈ A$2.3k/mo; comfortable (Bangkok/KL/Canggu) ≈ A$4k/mo — INCLUDING expat health cover (~A$200–500/mo). | Rent now $1,200/mo per Clent (was $3,500 scenario input) — SEA lean scenario is effectively his base plan.
A31: Keep the AU spine | B31: Medicare stays (resident); check Medibank suspension option (avoids LHC loading vs cancelling); ClearView life stays; kids’ school fee flows unchanged; Wise multi-currency for daily spend, keep NAB/trust accounts for business.
A32: Trial before lease | B32: Land Oct, run 4–6 weeks in 2 hubs before any 12-month lease. Timing works: settlement 27 Sep → fly early Oct.
A33: Obligations travel with you | B33: BCSA school-fee (50%) and medical (50%) obligations run to ~2030 (Sierra) / ~2032 (Kyah) in ALL scenarios — they're already inside every runway number; SEA doesn't change them.
A34: ACTIONS — NEXT 90 DAYS
A35: August | B35: Bridge: confirm Nick Walter's sell-down date and cleared date into Macquarie, then move funds Macquarie → NAB. Confirm 15 Aug lands Fri 14 or Mon 17 Aug (15 Aug is a Saturday). | C35: P1
A36: August | B36: Invoice WalterWealth and Adam Hall and get payment dates in writing. Every dollar received before 28 Sep reduces the second tranche. Chase the Lindisfarne 50% direct-invoicing switch (BCSA cl. 3.4) and confirm BCSA registration with Services Australia. | C36: P1
A37: September | B37: Book removalists for settlement week; pay on/after 28 Sep if the mover allows. Confirm storage start w/c 23 Sep. Settlement-day checklist with Border Conveyancing: final payout figure, commission invoice, adjustment for Tweed rates. | C37: P1
A38: Late September | B38: On settlement: repay the $25,000 to JIG immediately and tell TWB. Then allocate proceeds per plan (buffer vs deploy) and re-run runway with actuals. | C38: P1
A39: October | B39: Fly. Two-hub trial. Suspend/cancel AU-only services. Season ~A$21k for the DTV from proceeds; apply from ~Jan 2027. | C39: P2
A40: Ongoing | B40: Pipeline sprint: BTC funding decision date, EWU win-back, Meridiam/All Coast kick-offs. Enter July component actuals in 'Forecast vs Actual' from Xero — closing cash is in, the component rows are not. | C40: P2
...
